---
title: throw-try-catch
date: 2023-01-14
tags:
 - JavaScript
categories:
 - JavaScript
---

```
try 语句测试代码块的错误。
catch 语句处理错误。
throw 语句创建自定义错误。
finally 语句在 try 和 catch 语句之后，无论是否有触发异常，该语句都会执行。

语法
  try {
    ...    //异常的抛出
  } catch(e) {
    ...    //异常的捕获与处理
  } finally {
    ...    //结束处理
  }
```
## try 和 catch
```js
  // try 语句允许我们定义在执行时进行错误测试的代码块。
  // catch 语句允许我们定义当 try 代码块发生错误时，所执行的代码块。
  // JavaScript 语句 try 和 catch 是成对出现的。
  var txt = ''
  var test = () => {
      try {
          adddlert("123")
      } catch(err) {
          console.log(err.message)
      }
  }
  test() // adddlert is not defined
```
## finally 语句
```js
  // try 语句允许我们定义在执行时进行错误测试的代码块。
  // catch 语句允许我们定义当 try 代码块发生错误时，所执行的代码块。
  // JavaScript 语句 try 和 catch 是成对出现的。
  var txt = ''
  var test = () => {
      try {
          adddlert("123")
      } catch (err) {
          console.log(err.message)
      } finally {
          console.log('finally')
      }
  }
  test()
  // adddlert is not defined
  // finally
```

## Throw 语句
```js
// throw 语句允许我们创建自定义错误。
// 正确的技术术语是：创建或抛出异常（exception）。
// 如果把 throw 与 try 和 catch 一起使用，那么您能够控制程序流，并生成自定义的错误消息。
// 从 catch 中抛出错误
var txt = ''
    var test = (val) => {
        var num = val
        try {
            if (num < 5) throw "值小于5";
            if (num = 7) throw "值等于7";
            if (num > 10) throw "值大于10";
        } catch (err) {
            console.log(err)
        }
    }
    test(4) // 值小于5
    test(7) // 值等于7
    test(11) // 值大于10
```
